<?xml version="1.0" ?>
<!-- =================================================================================== -->
<!-- |    This document was autogenerated by xacro from /catkin_ws/src/pkg_ur10e_gripper/urdf/ur10e_robotiq_description.xacro | -->
<!-- |    EDITING THIS FILE BY HAND IS NOT RECOMMENDED                                 | -->
<!-- =================================================================================== -->
<robot name="ur10e_with_robotiq_2f_85">
    <!--
    Base UR robot series xacro macro.

    NOTE: this is NOT a URDF. It cannot directly be loaded by consumers
    expecting a flattened '.urdf' file. See the top-level '.xacro' for that
    (but note: that .xacro must still be processed by the xacro command).

    For use in '.launch' files: use one of the 'load_urX.launch' convenience
    launch files.

    This file models the base kinematic chain of a UR robot, which then gets
    parameterised by various configuration files to convert it into a UR3(e),
    UR5(e), UR10(e), UR16e, UR20 or UR30.

    NOTE: the default kinematic parameters (ie: link lengths, frame locations,
    offets, etc) do not correspond to any particular robot. They are defaults
    only. There WILL be non-zero offsets between the Forward Kinematics results
    in TF (ie: robot_state_publisher) and the values reported by the Teach
    Pendant.

    For accurate (and robot-specific) transforms, the 'kinematics_parameters_file'
    parameter MUST point to a .yaml file containing the appropriate values for
    the targetted robot.

    If using the UniversalRobots/Universal_Robots_ROS_Driver, follow the steps
    described in the readme of that repository to extract the kinematic
    calibration from the controller and generate the required .yaml file.

    Main author of the migration to yaml configs: Ludovic Delval.

    Contributors to previous versions (in no particular order):

     - Felix Messmer
     - Kelsey Hawkins
     - Wim Meeussen
     - Shaun Edwards
     - Nadia Hammoudeh Garcia
     - Dave Hershberger
     - G. vd. Hoorn
     - Philip Long
     - Dave Coleman
     - Miguel Prada
     - Mathias Luedtke
     - Marcel Schnirring
     - Felix von Drigalski
     - Felix Exner
     - Jimmy Da Silva
     - Ajit Krisshna N L
     - Muhammad Asif Rana
  -->
    <!--
    NOTE: the macro defined in this file is NOT part of the public API of this
          package. Users CANNOT rely on this file being available, or stored in
          this location. Nor can they rely on the existence of the macro.
  -->
    <transmission name="shoulder_pan_trans">
        <type>transmission_interface/SimpleTransmission</type>
        <joint name="shoulder_pan_joint">
            <hardwareInterface>hardware_interface/EffortJointInterface</hardwareInterface>
        </joint>
        <actuator name="shoulder_pan_motor">
            <mechanicalReduction>1</mechanicalReduction>
        </actuator>
    </transmission>
    <transmission name="shoulder_lift_trans">
        <type>transmission_interface/SimpleTransmission</type>
        <joint name="shoulder_lift_joint">
            <hardwareInterface>hardware_interface/EffortJointInterface</hardwareInterface>
        </joint>
        <actuator name="shoulder_lift_motor">
            <mechanicalReduction>1</mechanicalReduction>
        </actuator>
    </transmission>
    <transmission name="elbow_trans">
        <type>transmission_interface/SimpleTransmission</type>
        <joint name="elbow_joint">
            <hardwareInterface>hardware_interface/EffortJointInterface</hardwareInterface>
        </joint>
        <actuator name="elbow_motor">
            <mechanicalReduction>1</mechanicalReduction>
        </actuator>
    </transmission>
    <transmission name="wrist_1_trans">
        <type>transmission_interface/SimpleTransmission</type>
        <joint name="wrist_1_joint">
            <hardwareInterface>hardware_interface/EffortJointInterface</hardwareInterface>
        </joint>
        <actuator name="wrist_1_motor">
            <mechanicalReduction>1</mechanicalReduction>
        </actuator>
    </transmission>
    <transmission name="wrist_2_trans">
        <type>transmission_interface/SimpleTransmission</type>
        <joint name="wrist_2_joint">
            <hardwareInterface>hardware_interface/EffortJointInterface</hardwareInterface>
        </joint>
        <actuator name="wrist_2_motor">
            <mechanicalReduction>1</mechanicalReduction>
        </actuator>
    </transmission>
    <transmission name="wrist_3_trans">
        <type>transmission_interface/SimpleTransmission</type>
        <joint name="wrist_3_joint">
            <hardwareInterface>hardware_interface/EffortJointInterface</hardwareInterface>
        </joint>
        <actuator name="wrist_3_motor">
            <mechanicalReduction>1</mechanicalReduction>
        </actuator>
    </transmission>
    <!-- links: main serial chain -->
    <link name="world"/>
    <joint name="world_table_base_joint" type="fixed">
        <parent link="world"/>
        <child link="table_base_link"/>
        <origin rpy="0 0 0" xyz="0 0 0"/>
    </joint>
    
   <link
    name="table_base_link">
    <inertial>
      <origin
        xyz="0.302 0.89235 0.60135"
        rpy="0 0 0" />
      <mass
        value="189.62" />
      <inertia
        ixx="35.646"
        ixy="0.00096487"
        ixz="0.0011571"
        iyy="18.384"
        iyz="-0.00023075"
        izz="36.698" />
    </inertial>
    <visual>
      <origin
        xyz="0 0 0"
        rpy="0 0 0" />
      <geometry>
        <mesh
          filename="package://table/meshes/table_base_link.dae" />
      </geometry>
      <material
        name="">
        <color
          rgba="0 0.1 1 1" />
      </material>
    </visual>
    <collision>
      <origin
        xyz="0 0 0"
        rpy="0 0 0" />
      <geometry>
        <mesh
          filename="package://table/meshes/table_base_link.STL" />
      </geometry>
    </collision>
  </link>
  <link
    name="table_link">
    <inertial>
      <origin
        xyz="0 2.2204E-16 -0.0050153"
        rpy="0 0 0" />
      <mass
        value="3.0269" />
      <inertia
        ixx="0.0098356"
        ixy="-2.8639E-19"
        ixz="-4.5673E-20"
        iyy="0.0098188"
        iyz="1.6276E-18"
        izz="0.019604" />
    </inertial>
    <visual>
      <origin
        xyz="0 0 0"
        rpy="0 0 0" />
      <geometry>
        <mesh
          filename="package://table/meshes/table_link.STL" />
      </geometry>
      <material
        name="">
        <color
          rgba="0 0.1 1 1" />
      </material>
    </visual>
    <collision>
      <origin
        xyz="0 0 0"
        rpy="0 0 0" />
      <geometry>
        <mesh
          filename="package://table/meshes/table_link.STL" />
      </geometry>
    </collision>
  </link>
  <joint
    name="table_base_table_joint"
    type="fixed">
    <origin
      xyz="0.2 1.14 1.01"
      rpy="0 0 0" />
    <parent
      link="table_base_link" />
    <child
      link="table_link" />
    <axis
      xyz="0 0 0" />
  </joint>

    <joint name="table_base_joint" type="fixed">
        <parent link="table_link"/>
        <child link="base_link"/>
        <origin rpy="0 0 0" xyz="0 0 0.010"/>
    </joint>
    
    <link name="base_link" />
    <link name="base_link_inertia">
        <visual>
            <origin rpy="0 0 3.141592653589793" xyz="0 0 0" />
            <geometry>
                <mesh filename="package://ur_description/meshes/ur10e/visual/base.dae" />
            </geometry>
            <material name="LightGrey">
                <color rgba="0.7 0.7 0.7 1.0" />
            </material>
        </visual>
        <collision>
            <origin rpy="0 0 3.141592653589793" xyz="0 0 0" />
            <geometry>
                <mesh filename="package://ur_description/meshes/ur10e/collision/base.stl" />
            </geometry>
        </collision>
        <inertial>
            <mass value="4.0" />
            <origin rpy="0 0 0" xyz="0 0 0" />
            <inertia ixx="0.0061063308908" ixy="0.0" ixz="0.0" iyy="0.0061063308908" iyz="0.0" izz="0.01125" />
        </inertial>
    </link>
    <link name="shoulder_link">
        <visual>
            <origin rpy="0 0 3.141592653589793" xyz="0 0 0" />
            <geometry>
                <mesh filename="package://ur_description/meshes/ur10e/visual/shoulder.dae" />
            </geometry>
            <material name="LightGrey">
                <color rgba="0.7 0.7 0.7 1.0" />
            </material>
        </visual>
        <collision>
            <origin rpy="0 0 3.141592653589793" xyz="0 0 0" />
            <geometry>
                <mesh filename="package://ur_description/meshes/ur10e/collision/shoulder.stl" />
            </geometry>
        </collision>
        <inertial>
            <mass value="7.778" />
            <origin rpy="0 0 0" xyz="0 0 0" />
            <inertia ixx="0.03147431257693659" ixy="0.0" ixz="0.0" iyy="0.03147431257693659" iyz="0.0" izz="0.021875624999999996" />
        </inertial>
    </link>
    <link name="upper_arm_link">
        <visual>
            <origin rpy="1.5707963267948966 0 -1.5707963267948966" xyz="0 0 0.1762" />
            <geometry>
                <mesh filename="package://ur_description/meshes/ur10e/visual/upperarm.dae" />
            </geometry>
            <material name="LightGrey">
                <color rgba="0.7 0.7 0.7 1.0" />
            </material>
        </visual>
        <collision>
            <origin rpy="1.5707963267948966 0 -1.5707963267948966" xyz="0 0 0.1762" />
            <geometry>
                <mesh filename="package://ur_description/meshes/ur10e/collision/upperarm.stl" />
            </geometry>
        </collision>
        <inertial>
            <mass value="12.93" />
            <origin rpy="0 1.5707963267948966 0" xyz="-0.306 0.0 0.175" />
            <inertia ixx="0.42175380379841093" ixy="0.0" ixz="0.0" iyy="0.42175380379841093" iyz="0.0" izz="0.03636562499999999" />
        </inertial>
    </link>
    <link name="forearm_link">
        <visual>
            <origin rpy="1.5707963267948966 0 -1.5707963267948966" xyz="0 0 0.0393" />
            <geometry>
                <mesh filename="package://ur_description/meshes/ur10e/visual/forearm.dae" />
            </geometry>
            <material name="LightGrey">
                <color rgba="0.7 0.7 0.7 1.0" />
            </material>
        </visual>
        <collision>
            <origin rpy="1.5707963267948966 0 -1.5707963267948966" xyz="0 0 0.0393" />
            <geometry>
                <mesh filename="package://ur_description/meshes/ur10e/collision/forearm.stl" />
            </geometry>
        </collision>
        <inertial>
            <mass value="3.87" />
            <origin rpy="0 1.5707963267948966 0" xyz="-0.285775 0.0 0.0393" />
            <inertia ixx="0.11079302548902206" ixy="0.0" ixz="0.0" iyy="0.11079302548902206" iyz="0.0" izz="0.010884375" />
        </inertial>
    </link>
    <link name="wrist_1_link">
        <visual>
            <!-- TODO: Move this to a parameter -->
            <origin rpy="1.5707963267948966 0 0" xyz="0 0 -0.135" />
            <geometry>
                <mesh filename="package://ur_description/meshes/ur10e/visual/wrist1.dae" />
            </geometry>
            <material name="LightGrey">
                <color rgba="0.7 0.7 0.7 1.0" />
            </material>
        </visual>
        <collision>
            <origin rpy="1.5707963267948966 0 0" xyz="0 0 -0.135" />
            <geometry>
                <mesh filename="package://ur_description/meshes/ur10e/collision/wrist1.stl" />
            </geometry>
        </collision>
        <inertial>
            <mass value="1.96" />
            <origin rpy="0 0 0" xyz="0 0 0" />
            <inertia ixx="0.005108247956699999" ixy="0.0" ixz="0.0" iyy="0.005108247956699999" iyz="0.0" izz="0.005512499999999999" />
        </inertial>
    </link>
    <link name="wrist_2_link">
        <visual>
            <origin rpy="0 0 0" xyz="0 0 -0.12" />
            <geometry>
                <mesh filename="package://ur_description/meshes/ur10e/visual/wrist2.dae" />
            </geometry>
            <material name="LightGrey">
                <color rgba="0.7 0.7 0.7 1.0" />
            </material>
        </visual>
        <collision>
            <origin rpy="0 0 0" xyz="0 0 -0.12" />
            <geometry>
                <mesh filename="package://ur_description/meshes/ur10e/collision/wrist2.stl" />
            </geometry>
        </collision>
        <inertial>
            <mass value="1.96" />
            <origin rpy="0 0 0" xyz="0 0 0" />
            <inertia ixx="0.005108247956699999" ixy="0.0" ixz="0.0" iyy="0.005108247956699999" iyz="0.0" izz="0.005512499999999999" />
        </inertial>
    </link>
    <link name="wrist_3_link">
        <visual>
            <origin rpy="1.5707963267948966 0 0" xyz="0 0 -0.1168" />
            <geometry>
                <mesh filename="package://ur_description/meshes/ur10e/visual/wrist3.dae" />
            </geometry>
            <material name="LightGrey">
                <color rgba="0.7 0.7 0.7 1.0" />
            </material>
        </visual>
        <collision>
            <origin rpy="1.5707963267948966 0 0" xyz="0 0 -0.1168" />
            <geometry>
                <mesh filename="package://ur_description/meshes/ur10e/collision/wrist3.stl" />
            </geometry>
        </collision>
        <inertial>
            <mass value="0.202" />
            <origin rpy="0 0 0" xyz="0.0 0.0 -0.025" />
            <inertia ixx="0.00014434577559500002" ixy="0.0" ixz="0.0" iyy="0.00014434577559500002" iyz="0.0" izz="0.00020452500000000002" />
        </inertial>
    </link>
    <!-- joints: main serial chain -->
    <joint name="base_link-base_link_inertia" type="fixed">
        <parent link="base_link" />
        <child link="base_link_inertia" />
        <!-- 'base_link' is REP-103 aligned (so X+ forward), while the internal
           frames of the robot/controller have X+ pointing backwards.
           Use the joint between 'base_link' and 'base_link_inertia' (a dummy
           link/frame) to introduce the necessary rotation over Z (of pi rad).
      -->
        <origin rpy="0 0 3.141592653589793" xyz="0 0 0" />
    </joint>
    <joint name="shoulder_pan_joint" type="revolute">
        <parent link="base_link_inertia" />
        <child link="shoulder_link" />
        <origin rpy="0 0 0" xyz="0 0 0.1807" />
        <axis xyz="0 0 1" />
        <limit effort="330.0" lower="-6.283185307179586" upper="6.283185307179586" velocity="2.0943951023931953" />
        <dynamics damping="0.3" friction="0.1" />
    </joint>
    <joint name="shoulder_lift_joint" type="revolute">
        <parent link="shoulder_link" />
        <child link="upper_arm_link" />
        <origin rpy="1.570796327 0 0" xyz="0 0 0" />
        <axis xyz="0 0 1" />
        <limit effort="330.0" lower="-6.283185307179586" upper="6.283185307179586" velocity="2.0943951023931953" />
        <dynamics damping="0.3" friction="0.1" />
    </joint>
    <joint name="elbow_joint" type="revolute">
        <parent link="upper_arm_link" />
        <child link="forearm_link" />
        <origin rpy="0 0 0" xyz="-0.6127 0 0" />
        <axis xyz="0 0 1" />
        <limit effort="150.0" lower="-3.141592653589793" upper="3.141592653589793" velocity="3.141592653589793" />
        <dynamics damping="0.3" friction="0.1" />
    </joint>
    <joint name="wrist_1_joint" type="revolute">
        <parent link="forearm_link" />
        <child link="wrist_1_link" />
        <origin rpy="0 0 0" xyz="-0.57155 0 0.17415" />
        <axis xyz="0 0 1" />
        <limit effort="56.0" lower="-6.283185307179586" upper="6.283185307179586" velocity="3.141592653589793" />
        <dynamics damping="0.3" friction="0.1" />
    </joint>
    <joint name="wrist_2_joint" type="revolute">
        <parent link="wrist_1_link" />
        <child link="wrist_2_link" />
        <origin rpy="1.570796327 0 0" xyz="0 -0.11985 -2.458164590756244e-11" />
        <axis xyz="0 0 1" />
        <limit effort="56.0" lower="-6.283185307179586" upper="6.283185307179586" velocity="3.141592653589793" />
        <dynamics damping="0.3" friction="0.1" />
    </joint>
    <joint name="wrist_3_joint" type="revolute">
        <parent link="wrist_2_link" />
        <child link="wrist_3_link" />
        <origin rpy="1.570796326589793 3.141592653589793 3.141592653589793" xyz="0 0.11655 -2.390480459346185e-11" />
        <axis xyz="0 0 1" />
        <limit effort="56.0" lower="-6.283185307179586" upper="6.283185307179586" velocity="3.141592653589793" />
        <dynamics damping="0.3" friction="0.1" />
    </joint>
    <!-- ROS-Industrial 'base' frame: base_link to UR 'Base' Coordinates transform -->
    <link name="base" />
    <joint name="base_link-base_fixed_joint" type="fixed">
        <!-- Note the rotation over Z of pi radians: as base_link is REP-103
           aligned (ie: has X+ forward, Y+ left and Z+ up), this is needed
           to correctly align 'base' with the 'Base' coordinate system of
           the UR controller.
      -->
        <origin rpy="0 0 3.141592653589793" xyz="0 0 0" />
        <parent link="base_link" />
        <child link="base" />
    </joint>
    <!-- ROS-Industrial 'flange' frame: attachment point for EEF models -->
    <link name="flange" />
    <joint name="wrist_3-flange" type="fixed">
        <parent link="wrist_3_link" />
        <child link="flange" />
        <origin rpy="0 -1.5707963267948966 -1.5707963267948966" xyz="0 0 0" />
    </joint>
    <!-- ROS-Industrial 'tool0' frame: all-zeros tool frame -->
    <link name="tool0" />
    <joint name="flange-tool0" type="fixed">
        <!-- default toolframe: X+ left, Y+ up, Z+ front -->
        <origin rpy="1.5707963267948966 0 1.5707963267948966" xyz="0 0 0" />
        <parent link="flange" />
        <child link="tool0" />
    </joint>   
    
    <joint name="robotiq_85_base_joint" type="fixed">
        <parent link="tool0" />
        <child link="robotiq_85_base_link" />
        <origin rpy="0 -1.5707963267948966 3.141592653589793" xyz="0 0 0.007" />
    </joint>
    <link name="robotiq_85_base_link">
        <visual>
            <geometry>
                <mesh filename="package://robotiq_description/meshes/visual/robotiq_85_base_link.dae" />
            </geometry>
        </visual>
        <collision>
            <geometry>
                <mesh filename="package://robotiq_description/meshes/collision/robotiq_85_base_link.stl" />
            </geometry>
        </collision>
        <inertial>
            <mass value="0.636951" />
            <origin xyz="0.0 0.0 0.0" rpy="0 0 0" />
            <inertia ixx="0.000380" ixy="0.000000" ixz="0.000000" iyx="0.000000" iyy="0.001110" iyz="0.000000" izx="0.000000" izy="0.000000" izz="0.001171" />
        </inertial>
    </link>
    <joint name="robotiq_85_left_knuckle_joint" type="revolute">
        <parent link="robotiq_85_base_link" />
        <child link="robotiq_85_left_knuckle_link" />
        <axis xyz="0 0 1" />
        <origin rpy="3.141592653589793 0.0 0.0" xyz="0.05490451627 0.03060114443 0.0" />
        <limit effort="1000" lower="0.0" upper="0.80285" velocity="0.5" />
    </joint>
    <joint name="robotiq_85_right_knuckle_joint" type="revolute">
        <parent link="robotiq_85_base_link" />
        <child link="robotiq_85_right_knuckle_link" />
        <axis xyz="0 0 1" />
        <origin rpy="0.0 0.0 0.0" xyz="0.05490451627 -0.03060114443 0.0" />
        <limit effort="1000" lower="0" upper="0.80285" velocity="100.0" />
        <mimic joint="robotiq_85_left_knuckle_joint" />
    </joint>
    <link name="robotiq_85_left_knuckle_link">
        <visual>
            <geometry>
                <mesh filename="package://robotiq_description/meshes/visual/robotiq_85_knuckle_link.dae" />
            </geometry>
        </visual>
        <collision>
            <geometry>
                <mesh filename="package://robotiq_description/meshes/collision/robotiq_85_knuckle_link.stl" />
            </geometry>
        </collision>
        <inertial>
            <mass value="0.018491" />
            <origin xyz="0.0 0.0 0.0" rpy="0 0 0" />
            <inertia ixx="0.000009" ixy="-0.000001" ixz="0.000000" iyx="-0.000001" iyy="0.000001" iyz="0.000000" izx="0.000000" izy="0.000000" izz="0.000010" />
        </inertial>
    </link>
    <link name="robotiq_85_right_knuckle_link">
        <visual>
            <geometry>
                <mesh filename="package://robotiq_description/meshes/visual/robotiq_85_knuckle_link.dae" />
            </geometry>
        </visual>
        <collision>
            <geometry>
                <mesh filename="package://robotiq_description/meshes/collision/robotiq_85_knuckle_link.stl" />
            </geometry>
        </collision>
        <inertial>
            <mass value="0.018491" />
            <origin xyz="0.0 0.0 0.0" rpy="0 0 0" />
            <inertia ixx="0.000009" ixy="-0.000001" ixz="0.000000" iyx="-0.000001" iyy="0.000001" iyz="0.000000" izx="0.000000" izy="0.000000" izz="0.000010" />
        </inertial>
    </link>
    <joint name="robotiq_85_left_finger_joint" type="fixed">
        <parent link="robotiq_85_left_knuckle_link" />
        <child link="robotiq_85_left_finger_link" />
        <origin rpy="0 0 0" xyz="-0.00408552455 -0.03148604435 0.0" />
    </joint>
    <joint name="robotiq_85_right_finger_joint" type="fixed">
        <parent link="robotiq_85_right_knuckle_link" />
        <child link="robotiq_85_right_finger_link" />
        <origin rpy="0 0 0" xyz="-0.00408552455 -0.03148604435 0.0" />
    </joint>
    <link name="robotiq_85_left_finger_link">
        <visual>
            <geometry>
                <mesh filename="package://robotiq_description/meshes/visual/robotiq_85_finger_link.dae" />
            </geometry>
        </visual>
        <collision>
            <geometry>
                <mesh filename="package://robotiq_description/meshes/collision/robotiq_85_finger_link.stl" />
            </geometry>
        </collision>
        <inertial>
            <mass value="0.027309" />
            <origin xyz="0.0 0.0 0.0" rpy="0 0 0" />
            <inertia ixx="0.000003" ixy="-0.000002" ixz="0.000000" iyx="-0.000002" iyy="0.000021" iyz="0.000000" izx="0.000000" izy="0.000000" izz="0.000020" />
        </inertial>
    </link>
    <link name="robotiq_85_right_finger_link">
        <visual>
            <geometry>
                <mesh filename="package://robotiq_description/meshes/visual/robotiq_85_finger_link.dae" />
            </geometry>
        </visual>
        <collision>
            <geometry>
                <mesh filename="package://robotiq_description/meshes/collision/robotiq_85_finger_link.stl" />
            </geometry>
        </collision>
        <inertial>
            <mass value="0.027309" />
            <origin xyz="0.0 0.0 0.0" rpy="0 0 0" />
            <inertia ixx="0.000003" ixy="-0.000002" ixz="0.000000" iyx="-0.000002" iyy="0.000021" iyz="0.000000" izx="0.000000" izy="0.000000" izz="0.000020" />
        </inertial>
    </link>
    <joint name="robotiq_85_left_inner_knuckle_joint" type="revolute">
        <parent link="robotiq_85_base_link" />
        <child link="robotiq_85_left_inner_knuckle_link" />
        <axis xyz="0 0 1" />
        <origin rpy="3.141592653589793 0.0 0.0" xyz="0.06142 0.0127 0" />
        <limit effort="0.1" lower="0" upper="0.8757" velocity="100.0" />
        <mimic joint="robotiq_85_left_knuckle_joint" offset="0" />
    </joint>
    <joint name="robotiq_85_right_inner_knuckle_joint" type="revolute">
        <parent link="robotiq_85_base_link" />
        <child link="robotiq_85_right_inner_knuckle_link" />
        <axis xyz="0 0 1" />
        <origin rpy="0 0 0" xyz="0.06142 -0.0127 0" />
        <limit effort="0.1" lower="0" upper="0.8757" velocity="100.0" />
        <mimic joint="robotiq_85_left_knuckle_joint" offset="0" />
    </joint>
    <link name="robotiq_85_left_inner_knuckle_link">
        <visual>
            <geometry>
                <mesh filename="package://robotiq_description/meshes/visual/robotiq_85_inner_knuckle_link.dae" />
            </geometry>
        </visual>
        <collision>
            <geometry>
                <mesh filename="package://robotiq_description/meshes/collision/robotiq_85_inner_knuckle_link.stl" />
            </geometry>
        </collision>
        <inertial>
            <mass value="0.029951" />
            <origin xyz="0.0 0.0 0.0" rpy="0 0 0" />
            <inertia ixx="0.000039" ixy="0.000000" ixz="0.000000" iyx="0.000000" iyy="0.000005" iyz="0.000000" izx="0.000000" izy="0.000000" izz="0.000035" />
        </inertial>
    </link>
    <link name="robotiq_85_right_inner_knuckle_link">
        <visual>
            <geometry>
                <mesh filename="package://robotiq_description/meshes/visual/robotiq_85_inner_knuckle_link.dae" />
            </geometry>
        </visual>
        <collision>
            <geometry>
                <mesh filename="package://robotiq_description/meshes/collision/robotiq_85_inner_knuckle_link.stl" />
            </geometry>
        </collision>
        <inertial>
            <mass value="0.029951" />
            <origin xyz="0.0 0.0 0.0" rpy="0 0 0" />
            <inertia ixx="0.000039" ixy="0.000000" ixz="0.000000" iyx="0.000000" iyy="0.000005" iyz="0.000000" izx="0.000000" izy="0.000000" izz="0.000035" />
        </inertial>
    </link>
    <joint name="robotiq_85_left_finger_tip_joint" type="revolute">
        <parent link="robotiq_85_left_inner_knuckle_link" />
        <child link="robotiq_85_left_finger_tip_link" />
        <axis xyz="0 0 1" />
        <origin rpy="0.0 0.0 0.0" xyz="0.04303959807 -0.03759940821 0.0" />
        <limit effort="0.1" lower="-3.14" upper="3.14" velocity="100.0" />
        <mimic joint="robotiq_85_left_knuckle_joint" multiplier="-1" />
    </joint>
    <joint name="robotiq_85_right_finger_tip_joint" type="revolute">
        <parent link="robotiq_85_right_inner_knuckle_link" />
        <child link="robotiq_85_right_finger_tip_link" />
        <axis xyz="0 0 1" />
        <origin rpy="0.0 0.0 0.0" xyz="0.04303959807 -0.03759940821  0.0" />
        <limit effort="0.1" lower="-3.14" upper="3.14" velocity="100.0" />
        <mimic joint="robotiq_85_left_knuckle_joint" multiplier="-1" />
    </joint>
    <link name="robotiq_85_left_finger_tip_link">
        <visual>
            <geometry>
                <mesh filename="package://robotiq_description/meshes/visual/robotiq_85_finger_tip_link.dae" />
            </geometry>
        </visual>
        <collision>
            <geometry>
                <mesh filename="package://robotiq_description/meshes/collision/robotiq_85_finger_tip_link.stl" />
            </geometry>
        </collision>
        <inertial>
            <mass value="0.019555" />
            <origin xyz="0.0 0.0 0.0" rpy="0 0 0" />
            <inertia ixx="0.000002" ixy="0.000000" ixz="0.000000" iyx="0.000000" iyy="0.000005" iyz="0.000000" izx="0.000000" izy="0.000000" izz="0.000006" />
        </inertial>
    </link>
    <link name="robotiq_85_right_finger_tip_link">
        <visual>
            <geometry>
                <mesh filename="package://robotiq_description/meshes/visual/robotiq_85_finger_tip_link.dae" />
            </geometry>
        </visual>
        <collision>
            <geometry>
                <mesh filename="package://robotiq_description/meshes/collision/robotiq_85_finger_tip_link.stl" />
            </geometry>
        </collision>
        <inertial>
            <mass value="0.019555" />
            <origin xyz="0.0 0.0 0.0" rpy="0 0 0" />
            <inertia ixx="0.000002" ixy="0.000000" ixz="0.000000" iyx="0.000000" iyy="0.000005" iyz="0.000000" izx="0.000000" izy="0.000000" izz="0.000006" />
        </inertial>
    </link>
    <!-- Improve grasping physics -->
    <gazebo>
        <plugin name="gazebo_ros_control" filename="libgazebo_ros_control.so">
            <robotNamespace>/</robotNamespace>
        </plugin>
    </gazebo>

    <gazebo reference="robotiq_85_left_finger_tip_link">
        <kp>1000000.0</kp>
        <kd>1.0</kd>
        <mu1>1.0</mu1>
        <mu2>1.0</mu2>
        <minDepth>0.001</minDepth>
    </gazebo>
    <gazebo reference="robotiq_85_right_finger_tip_link">
        <kp>1000000.0</kp>
        <kd>1.0</kd>
        <mu1>1.0</mu1>
        <mu2>1.0</mu2>
        <minDepth>0.001</minDepth>
    </gazebo>
    <transmission name="robotiq_85_left_knuckle_trans">
        <type>transmission_interface/SimpleTransmission</type>
        <joint name="robotiq_85_left_knuckle_joint">
            <hardwareInterface>hardware_interface/EffortJointInterface</hardwareInterface>
        </joint>
        <actuator name="robotiq_85_left_knuckle_motor">
            <mechanicalReduction>1</mechanicalReduction>
            <hardwareInterface>hardware_interface/EffortJointInterface</hardwareInterface>
        </actuator>
    </transmission>
    <!-- Mimic joints -->
    <gazebo>
        <plugin filename="libroboticsgroup_gazebo_mimic_joint_plugin.so" name="mimic_robotiq_85_1">
            <joint>robotiq_85_left_knuckle_joint</joint>
            <mimicJoint>robotiq_85_right_knuckle_joint</mimicJoint>
        </plugin>
        <plugin filename="libroboticsgroup_gazebo_mimic_joint_plugin.so" name="mimic_robotiq_85_2">
            <joint>robotiq_85_left_knuckle_joint</joint>
            <mimicJoint>robotiq_85_left_inner_knuckle_joint</mimicJoint>
        </plugin>
        <plugin filename="libroboticsgroup_gazebo_mimic_joint_plugin.so" name="mimic_robotiq_85_3">
            <joint>robotiq_85_left_knuckle_joint</joint>
            <mimicJoint>robotiq_85_right_inner_knuckle_joint</mimicJoint>
        </plugin>
        <plugin filename="libroboticsgroup_gazebo_mimic_joint_plugin.so" name="mimic_robotiq_85_4">
            <joint>robotiq_85_left_knuckle_joint</joint>
            <mimicJoint>robotiq_85_left_finger_tip_joint</mimicJoint>
            <multiplier>-1.0</multiplier>
            <offset>0.0</offset>
        </plugin>
        <plugin filename="libroboticsgroup_gazebo_mimic_joint_plugin.so" name="mimic_robotiq_85_5">
            <joint>robotiq_85_left_knuckle_joint</joint>
            <mimicJoint>robotiq_85_right_finger_tip_joint</mimicJoint>
            <multiplier>-1.0</multiplier>
            <offset>0.0</offset>
        </plugin>
    </gazebo>
    <transmission name="trans_robotiq_85_right_knuckle_joint">
        <type>transmission_interface/SimpleTransmission</type>
        <joint name="robotiq_85_right_knuckle_joint">
            <hardwareInterface>hardware_interface/EffortJointInterface</hardwareInterface>
        </joint>
        <actuator name="robotiq_85_right_knuckle_joint_motor">
            <hardwareInterface>hardware_interface/EffortJointInterface</hardwareInterface>
            <mechanicalReduction>1</mechanicalReduction>
        </actuator>
    </transmission>
    <transmission name="trans_robotiq_85_left_inner_knuckle_joint">
        <type>transmission_interface/SimpleTransmission</type>
        <joint name="robotiq_85_left_inner_knuckle_joint">
            <hardwareInterface>hardware_interface/EffortJointInterface</hardwareInterface>
        </joint>
        <actuator name="robotiq_85_left_inner_knuckle_joint_motor">
            <hardwareInterface>hardware_interface/EffortJointInterface</hardwareInterface>
            <mechanicalReduction>1</mechanicalReduction>
        </actuator>
    </transmission>
    <transmission name="trans_robotiq_85_right_inner_knuckle_joint">
        <type>transmission_interface/SimpleTransmission</type>
        <joint name="robotiq_85_right_inner_knuckle_joint">
            <hardwareInterface>hardware_interface/EffortJointInterface</hardwareInterface>
        </joint>
        <actuator name="robotiq_85_right_inner_knuckle_joint_motor">
            <hardwareInterface>hardware_interface/EffortJointInterface</hardwareInterface>
            <mechanicalReduction>1</mechanicalReduction>
        </actuator>
    </transmission>
    <transmission name="trans_robotiq_85_left_finger_tip_joint">
        <type>transmission_interface/SimpleTransmission</type>
        <joint name="robotiq_85_left_finger_tip_joint">
            <hardwareInterface>hardware_interface/EffortJointInterface</hardwareInterface>
        </joint>
        <actuator name="robotiq_85_left_finger_tip_joint_motor">
            <hardwareInterface>hardware_interface/EffortJointInterface</hardwareInterface>
            <mechanicalReduction>1</mechanicalReduction>
        </actuator>
    </transmission>
    <transmission name="trans_robotiq_85_right_finger_tip_joint">
        <type>transmission_interface/SimpleTransmission</type>
        <joint name="robotiq_85_right_finger_tip_joint">
            <hardwareInterface>hardware_interface/EffortJointInterface</hardwareInterface>
        </joint>
        <actuator name="robotiq_85_right_finger_tip_joint_motor">
            <hardwareInterface>hardware_interface/EffortJointInterface</hardwareInterface>
            <mechanicalReduction>1</mechanicalReduction>
        </actuator>
    </transmission>

    <joint name="camera_joint" type="fixed">
        <origin xyz="0.3 -0.8 1.0" rpy="0 1.5708 0" />
        <parent link="base_link"/>
        <child link="camera_link"/>
    </joint>
    <!-- Create camera reference frame -->
    <link name="camera_link">
    	<visual>
    	    <origin xyz="0.0 0.0 0.0" rpy="-1.5708 1.5708 0" />
            <geometry>
                <mesh filename="package://scanner/meshes/visual/scanner.dae" />
            </geometry>
        </visual>
        <collision>
            <origin xyz="0.0 0.0 0.0" rpy="-1.5708 1.5708 0" />
            <geometry>
                <mesh filename="package://scanner/meshes/collision/scanner.stl" />
            </geometry>
        </collision>
        <inertial>
            <mass value="0.1" />
            <origin xyz="0 0 0" />
            <inertia ixx="0.01" ixy="0.0" ixz="0.0"
                        iyy="0.01" iyz="0.0"
                        izz="0.01" />
        </inertial>

        <!-- <visual>
            <origin xyz=" 0 0 0 " rpy="0 0 0" />
            <geometry>
                <box size="0.10 0.30 0.20" />
            </geometry>
        </visual>

        <collision>
            <origin xyz="0.0 0.0 0.0" rpy="1.5708 0 0" />
            <geometry>
                <box size="0.10 0.30 0.20" />
            </geometry>
        </collision> -->
    </link>

    <!-- 在RVIZ中显示点云位姿错误，此处加入一个空连杆和空关节，用于调整点云tf位姿 -->
    <link name="camera_link_fake"></link>
    <joint name="camera_joint_fake" type="fixed">
        <origin xyz="0 0 0" rpy="-1.5708 0 -1.5708 "/>
        <parent link="camera_link"/>
        <child link="camera_link_fake"/>
    </joint>

    <gazebo reference="camera_link">
        <material>Gazebo/Black</material>
    </gazebo>

    <gazebo reference="camera_link">
        <sensor type="depth" name="camera_node">
            <update_rate>20.0</update_rate>
            <camera name="head">
                <horizontal_fov>1.3962634</horizontal_fov>
                <image>
                    <width>640</width>
                    <height>480</height>
                    <format>R8G8B8</format>
                </image>
                <clip>
                    <near>0.02</near>
                    <far>3</far>
                </clip>
                <noise>
                    <type>gaussian</type>
                    <mean>0.0</mean>
                    <stddev>0.007</stddev>
                </noise>
            </camera>
            
            <plugin name="camera_plugin" filename="libgazebo_ros_openni_kinect.so">
                <baseline>0.2</baseline>
                <alwaysOn>true</alwaysOn>
                <!-- Keep this zero, update_rate in the parent <sensor> tag
                    will control the frame rate. -->
                <updateRate>0.0</updateRate>
                <cameraName>camera_ir</cameraName>
                <imageTopicName>/camera/color/image_raw</imageTopicName>
                <cameraInfoTopicName>/camera/color/camera_info</cameraInfoTopicName>
                <depthImageTopicName>/camera/depth/image_raw</depthImageTopicName>
                <depthImageCameraInfoTopicName>/camera/depth/camera_info</depthImageCameraInfoTopicName>
                <pointCloudTopicName>/camera/depth/points</pointCloudTopicName>
                <frameName>camera_link_fake</frameName>
                <pointCloudCutoff>0.5</pointCloudCutoff>
                <pointCloudCutoffMax>1.1</pointCloudCutoffMax>
                <distortionK1>0</distortionK1>
                <distortionK2>0</distortionK2>
                <distortionK3>0</distortionK3>
                <distortionT1>0</distortionT1>
                <distortionT2>0</distortionT2>
                <CxPrime>0</CxPrime>
                <Cx>0</Cx>
                <Cy>0</Cy>
                <focalLength>0</focalLength>
                <hackBaseline>0</hackBaseline>
            </plugin>

        </sensor>
    </gazebo>

    <gazebo>
     <plugin name="gazebo_grasp_fix" filename="libgazebo_grasp_fix.so">
           <arm>
             <arm_name>ur10e_gripper</arm_name>
             <palm_link>wrist_3_link</palm_link>
             <gripper_link>robotiq_85_left_finger_tip_link</gripper_link>
             <gripper_link>robotiq_85_right_finger_tip_link</gripper_link>
             <gripper_link>robotiq_85_right_knuckle_link</gripper_link>
             <gripper_link>robotiq_85_left_knuckle_link</gripper_link>
             <gripper_link>robotiq_85_left_inner_knuckle_link</gripper_link>
             <gripper_link>robotiq_85_right_inner_knuckle_link</gripper_link>
           </arm>
       <forces_angle_tolerance>150</forces_angle_tolerance>
       <update_rate>130</update_rate>
       <grip_count_threshold>2</grip_count_threshold>
       <max_grip_count>8</max_grip_count>
       <release_tolerance>0.001</release_tolerance>
       <disable_collisions_on_attach>true</disable_collisions_on_attach>
       <contact_topic>__default_topic__</contact_topic>
     </plugin>
    </gazebo>
</robot>

